Workbook
Name Date_1: OFFSET(#REF!,,,1,#REF!)
Name margem_di: '[1]Margem Teorica Maxima'!$I$4:$M$45
Name S_1: OFFSET([2]backgroundcixn!$D$10:$KY$10,,,1,[2]CIXN!$G$2)
Name S_10: OFFSET([2]backgroundcixn!$D$60:$KY$60,,,1,[2]CIXN!$G$2)
Name S_11: OFFSET([2]backgroundcixn!$D$70:$KY$70,,,1,[2]CIXN!$G$2)
Name S_12: OFFSET([2]backgroundcixn!$D$80:$KY$80,,,1,[2]CIXN!$G$2)
Name S_13: OFFSET([2]backgroundcixn!$D$130:$KY$130,,,1,[2]CIXN!$G$2)
Name S_14: OFFSET([2]backgroundcixn!$D$140:$KY$140,,,1,[2]CIXN!$G$2)
Name S_15: OFFSET([2]backgroundcixn!$D$150:$KY$150,,,1,[2]CIXN!$G$2)
Name S_16: OFFSET([2]backgroundcixn!$D$160:$KY$160,,,1,[2]CIXN!$G$2)
Name S_2: OFFSET([2]backgroundcixn!$D$20:$KY$20,,,1,[2]CIXN!$G$2)
Name S_3: OFFSET([2]backgroundcixn!$D$30:$KY$30,,,1,[2]CIXN!$G$2)
Name S_4: OFFSET([2]backgroundcixn!$D$40:$KY$40,,,1,[2]CIXN!$G$2)
Name S_5: OFFSET([2]backgroundcixn!$D$90:$KY$90,,,1,[2]CIXN!$G$2)
Name S_6: OFFSET([2]backgroundcixn!$D$100:$KY$100,,,1,[2]CIXN!$G$2)
Name S_7: OFFSET([2]backgroundcixn!$D$110:$KY$110,,,1,[2]CIXN!$G$2)
Name S_8: OFFSET([2]backgroundcixn!$D$120:$KY$120,,,1,[2]CIXN!$G$2)
Name S_9: OFFSET([2]backgroundcixn!$D$50:$KY$50,,,1,[2]CIXN!$G$2)
Name var: OFFSET('[3]COD data'!XEV1048573, 0, 0, 1, '[3]COD data'!XEX1048565)

Sheet SR3
A1: SR3 | B1: CME
A2: SR3 | B2: instrument ID | C2: Name | D2: Ask | E2: Bid | F2: Last | G2: CTQ | H2: Settle | I2: Status | J2: CTQ | K2: Mid | L2: Last
A3: =$A$2&LEFT('cont list_bg'!G6,1)&RIGHT('cont list_bg'!G6,1) -> SR3H6 | B3: =RTD("tt.rtd",,"Inst",$B$1,$A3) -> 2264814074172926158 | C3: =RIGHT(RTD("tt.rtd",,$B3,C$2),2) -> H6 | D3: =RTD("tt.rtd",,$B3,D$2) -> 96.3775 | E3: =RTD("tt.rtd",,$B3,E$2) -> 96.3750 | F3: =RTD("tt.rtd",,$B3,F$2) -> 96.3775 | G3: =RTD("tt.rtd",,$B3,G$2) -> 1 | H3: =RTD("tt.rtd",,$B3,H$2) -> 96.3750 | I3: =RTD("tt.rtd",,$B3,I$2) -> Open | J3: =RTD("tt.rtd",,$B3,J$2) -> 1 | K3: =IFERROR(IF(I3="Open",(E3+D3)/2,H3),H3) -> 96.37625 | L3: =IF(AND(I3="Open",G3>0),F3,K3) -> 96.3775
A4: =$A$2&LEFT('cont list_bg'!G7,1)&RIGHT('cont list_bg'!G7,1) -> SR3M6 | B4: =RTD("tt.rtd",,"Inst",$B$1,$A4) -> 2518875037886751798 | C4: =RIGHT(RTD("tt.rtd",,$B4,C$2),2) -> M6 | D4: =RTD("tt.rtd",,$B4,D$2) -> 96.3500 | E4: =RTD("tt.rtd",,$B4,E$2) -> 96.3475 | F4: =RTD("tt.rtd",,$B4,F$2) -> 96.3500 | G4: =RTD("tt.rtd",,$B4,G$2) -> 4139 | H4: =RTD("tt.rtd",,$B4,H$2) -> 96.3325 | I4: =RTD("tt.rtd",,$B4,I$2) -> Open | J4: =RTD("tt.rtd",,$B4,J$2) -> 4139 | K4: =IFERROR(IF(I4="Open",(E4+D4)/2,H4),H4) -> 96.34875 | L4: =IF(AND(I4="Open",G4>0),F4,K4) -> 96.3500
A5: =$A$2&LEFT('cont list_bg'!G8,1)&RIGHT('cont list_bg'!G8,1) -> SR3U6 | B5: =RTD("tt.rtd",,"Inst",$B$1,$A5) -> 10056698436755136015 | C5: =RIGHT(RTD("tt.rtd",,$B5,C$2),2) -> U6 | D5: =RTD("tt.rtd",,$B5,D$2) -> 96.290 | E5: =RTD("tt.rtd",,$B5,E$2) -> 96.285 | F5: =RTD("tt.rtd",,$B5,F$2) -> 96.285 | G5: =RTD("tt.rtd",,$B5,G$2) -> 43 | H5: =RTD("tt.rtd",,$B5,H$2) -> 96.220 | I5: =RTD("tt.rtd",,$B5,I$2) -> Open | J5: =RTD("tt.rtd",,$B5,J$2) -> 43 | K5: =IFERROR(IF(I5="Open",(E5+D5)/2,H5),H5) -> 96.2875 | L5: =IF(AND(I5="Open",G5>0),F5,K5) -> 96.285
A6: =$A$2&LEFT('cont list_bg'!G9,1)&RIGHT('cont list_bg'!G9,1) -> SR3Z6 | B6: =RTD("tt.rtd",,"Inst",$B$1,$A6) -> 3761391845186607269 | C6: =RIGHT(RTD("tt.rtd",,$B6,C$2),2) -> Z6 | D6: =RTD("tt.rtd",,$B6,D$2) -> 96.195 | E6: =RTD("tt.rtd",,$B6,E$2) -> 96.190 | F6: =RTD("tt.rtd",,$B6,F$2) -> 96.190 | G6: =RTD("tt.rtd",,$B6,G$2) -> 200 | H6: =RTD("tt.rtd",,$B6,H$2) -> 96.085 | I6: =RTD("tt.rtd",,$B6,I$2) -> Open | J6: =RTD("tt.rtd",,$B6,J$2) -> 200 | K6: =IFERROR(IF(I6="Open",(E6+D6)/2,H6),H6) -> 96.1925 | L6: =IF(AND(I6="Open",G6>0),F6,K6) -> 96.190
A7: =$A$2&LEFT('cont list_bg'!G10,1)&RIGHT('cont list_bg'!G10,1) -> SR3H7 | B7: =RTD("tt.rtd",,"Inst",$B$1,$A7) -> 8786029629332899618 | C7: =RIGHT(RTD("tt.rtd",,$B7,C$2),2) -> H7 | D7: =RTD("tt.rtd",,$B7,D$2) -> 96.110 | E7: =RTD("tt.rtd",,$B7,E$2) -> 96.105 | F7: =RTD("tt.rtd",,$B7,F$2) -> 96.105 | G7: =RTD("tt.rtd",,$B7,G$2) -> 345 | H7: =RTD("tt.rtd",,$B7,H$2) -> 95.970 | I7: =RTD("tt.rtd",,$B7,I$2) -> Open | J7: =RTD("tt.rtd",,$B7,J$2) -> 345 | K7: =IFERROR(IF(I7="Open",(E7+D7)/2,H7),H7) -> 96.1075 | L7: =IF(AND(I7="Open",G7>0),F7,K7) -> 96.105
A8: =$A$2&LEFT('cont list_bg'!G11,1)&RIGHT('cont list_bg'!G11,1) -> SR3M7 | B8: =RTD("tt.rtd",,"Inst",$B$1,$A8) -> 6064266935547558467 | C8: =RIGHT(RTD("tt.rtd",,$B8,C$2),2) -> M7 | D8: =RTD("tt.rtd",,$B8,D$2) -> 96.075 | E8: =RTD("tt.rtd",,$B8,E$2) -> 96.070 | F8: =RTD("tt.rtd",,$B8,F$2) -> 96.075 | G8: =RTD("tt.rtd",,$B8,G$2) -> 15 | H8: =RTD("tt.rtd",,$B8,H$2) -> 95.930 | I8: =RTD("tt.rtd",,$B8,I$2) -> Open | J8: =RTD("tt.rtd",,$B8,J$2) -> 15 | K8: =IFERROR(IF(I8="Open",(E8+D8)/2,H8),H8) -> 96.0725 | L8: =IF(AND(I8="Open",G8>0),F8,K8) -> 96.075
A9: =$A$2&LEFT('cont list_bg'!G12,1)&RIGHT('cont list_bg'!G12,1) -> SR3U7 | B9: =RTD("tt.rtd",,"Inst",$B$1,$A9) -> 10582686653072545408 | C9: =RIGHT(RTD("tt.rtd",,$B9,C$2),2) -> U7 | D9: =RTD("tt.rtd",,$B9,D$2) -> 96.085 | E9: =RTD("tt.rtd",,$B9,E$2) -> 96.080 | F9: =RTD("tt.rtd",,$B9,F$2) -> 96.080 | G9: =RTD("tt.rtd",,$B9,G$2) -> 42 | H9: =RTD("tt.rtd",,$B9,H$2) -> 95.945 | I9: =RTD("tt.rtd",,$B9,I$2) -> Open | J9: =RTD("tt.rtd",,$B9,J$2) -> 42 | K9: =IFERROR(IF(I9="Open",(E9+D9)/2,H9),H9) -> 96.0825 | L9: =IF(AND(I9="Open",G9>0),F9,K9) -> 96.080
A10: =$A$2&LEFT('cont list_bg'!G13,1)&RIGHT('cont list_bg'!G13,1) -> SR3Z7 | B10: =RTD("tt.rtd",,"Inst",$B$1,$A10) -> 17925935412019565973 | C10: =RIGHT(RTD("tt.rtd",,$B10,C$2),2) -> Z7 | D10: =RTD("tt.rtd",,$B10,D$2) -> 96.125 | E10: =RTD("tt.rtd",,$B10,E$2) -> 96.120 | F10: =RTD("tt.rtd",,$B10,F$2) -> 96.120 | G10: =RTD("tt.rtd",,$B10,G$2) -> 486 | H10: =RTD("tt.rtd",,$B10,H$2) -> 95.990 | I10: =RTD("tt.rtd",,$B10,I$2) -> Open | J10: =RTD("tt.rtd",,$B10,J$2) -> 486 | K10: =IFERROR(IF(I10="Open",(E10+D10)/2,H10),H10) -> 96.1225 | L10: =IF(AND(I10="Open",G10>0),F10,K10) -> 96.120
A11: =$A$2&LEFT('cont list_bg'!G14,1)&RIGHT('cont list_bg'!G14,1) -> SR3H8 | B11: =RTD("tt.rtd",,"Inst",$B$1,$A11) -> 3822227243959035490 | C11: =RIGHT(RTD("tt.rtd",,$B11,C$2),2) -> H8 | D11: =RTD("tt.rtd",,$B11,D$2) -> 96.150 | E11: =RTD("tt.rtd",,$B11,E$2) -> 96.145 | F11: =RTD("tt.rtd",,$B11,F$2) -> 96.145 | G11: =RTD("tt.rtd",,$B11,G$2) -> 478 | H11: =RTD("tt.rtd",,$B11,H$2) -> 96.020 | I11: =RTD("tt.rtd",,$B11,I$2) -> Open | J11: =RTD("tt.rtd",,$B11,J$2) -> 478 | K11: =IFERROR(IF(I11="Open",(E11+D11)/2,H11),H11) -> 96.1475 | L11: =IF(AND(I11="Open",G11>0),F11,K11) -> 96.145
A12: =$A$2&LEFT('cont list_bg'!G15,1)&RIGHT('cont list_bg'!G15,1) -> SR3M8 | B12: =RTD("tt.rtd",,"Inst",$B$1,$A12) -> 12741923103719175711 | C12: =RIGHT(RTD("tt.rtd",,$B12,C$2),2) -> M8 | D12: =RTD("tt.rtd",,$B12,D$2) -> 96.145 | E12: =RTD("tt.rtd",,$B12,E$2) -> 96.140 | F12: =RTD("tt.rtd",,$B12,F$2) -> 96.140 | G12: =RTD("tt.rtd",,$B12,G$2) -> 143 | H12: =RTD("tt.rtd",,$B12,H$2) -> 96.020 | I12: =RTD("tt.rtd",,$B12,I$2) -> Open | J12: =RTD("tt.rtd",,$B12,J$2) -> 143 | K12: =IFERROR(IF(I12="Open",(E12+D12)/2,H12),H12) -> 96.1425 | L12: =IF(AND(I12="Open",G12>0),F12,K12) -> 96.140
A13: =$A$2&LEFT('cont list_bg'!G16,1)&RIGHT('cont list_bg'!G16,1) -> SR3U8 | B13: =RTD("tt.rtd",,"Inst",$B$1,$A13) -> 16673841811510079166 | C13: =RIGHT(RTD("tt.rtd",,$B13,C$2),2) -> U8 | D13: =RTD("tt.rtd",,$B13,D$2) -> 96.125 | E13: =RTD("tt.rtd",,$B13,E$2) -> 96.120 | F13: =RTD("tt.rtd",,$B13,F$2) -> 96.120 | G13: =RTD("tt.rtd",,$B13,G$2) -> 219 | H13: =RTD("tt.rtd",,$B13,H$2) -> 96.005 | I13: =RTD("tt.rtd",,$B13,I$2) -> Open | J13: =RTD("tt.rtd",,$B13,J$2) -> 219 | K13: =IFERROR(IF(I13="Open",(E13+D13)/2,H13),H13) -> 96.1225 | L13: =IF(AND(I13="Open",G13>0),F13,K13) -> 96.120
A14: =$A$2&LEFT('cont list_bg'!G17,1)&RIGHT('cont list_bg'!G17,1) -> SR3Z8 | B14: =RTD("tt.rtd",,"Inst",$B$1,$A14) -> 7359239446017790966 | C14: =RIGHT(RTD("tt.rtd",,$B14,C$2),2) -> Z8 | D14: =RTD("tt.rtd",,$B14,D$2) -> 96.100 | E14: =RTD("tt.rtd",,$B14,E$2) -> 96.095 | F14: =RTD("tt.rtd",,$B14,F$2) -> 96.095 | G14: =RTD("tt.rtd",,$B14,G$2) -> 5 | H14: =RTD("tt.rtd",,$B14,H$2) -> 95.990 | I14: =RTD("tt.rtd",,$B14,I$2) -> Open | J14: =RTD("tt.rtd",,$B14,J$2) -> 5 | K14: =IFERROR(IF(I14="Open",(E14+D14)/2,H14),H14) -> 96.0975 | L14: =IF(AND(I14="Open",G14>0),F14,K14) -> 96.095
... A27: =$A$2&LEFT('cont list_bg'!G30,1)&RIGHT('cont list_bg'!G30,1) -> SR3H2 | B27: =RTD("tt.rtd",,"Inst",$B$1,$A27) -> 11954488268734512343 | C27: =RIGHT(RTD("tt.rtd",,$B27,C$2),2) -> H2 | D27: =RTD("tt.rtd",,$B27,D$2) -> 95.695 | E27: =RTD("tt.rtd",,$B27,E$2) -> 95.655 | F27: =RTD("tt.rtd",,$B27,F$2) -> 95.625 | G27: =RTD("tt.rtd",,$B27,G$2) -> 4 | H27: =RTD("tt.rtd",,$B27,H$2) -> 95.580 | I27: =RTD("tt.rtd",,$B27,I$2) -> Open | J27: =RTD("tt.rtd",,$B27,J$2) -> 4 | K27: =IFERROR(IF(I27="Open",(E27+D27)/2,H27),H27) -> 95.675 | L27: =IF(AND(I27="Open",G27>0),F27,K27) -> 95.625

Sheet ER
A1: ER | B1: ICE_L
A2: I | B2: instrument ID | C2: Name | D2: Ask | E2: Bid | F2: Last | G2: CTQ | H2: Settle | I2: Status | J2: CTQ | K2: Mid | L2: Last
A3: =$A$2&" FM"&LEFT('cont list_bg'!C6,1)&"00"&RIGHT('cont list_bg'!C6,2)&"!" -> I FMH0026!
A4: =$A$2&" FM"&LEFT('cont list_bg'!C7,1)&"00"&RIGHT('cont list_bg'!C7,2)&"!" -> I FMM0026! | B4: =RTD("tt.rtd",,"Inst",$B$1,$A4) -> 5444827104880269937 | C4: =MID(RTD("tt.rtd",,$B4,C$2),7,1)&MID(RTD("tt.rtd",,$B4,C$2),11,1) -> M6 | D4: =RTD("tt.rtd",,$B4,D$2) -> "services.rtd.subscriptionError" | E4: =RTD("tt.rtd",,$B4,E$2) -> "services.rtd.subscriptionError" | F4: =RTD("tt.rtd",,$B4,F$2) -> "services.rtd.subscriptionError" | G4: =RTD("tt.rtd",,$B4,G$2) -> "services.rtd.subscriptionError" | H4: =RTD("tt.rtd",,$B4,H$2) -> "services.rtd.subscriptionError" | I4: =RTD("tt.rtd",,$B4,I$2) -> "services.rtd.subscriptionError" | J4: =RTD("tt.rtd",,$B4,J$2) -> "services.rtd.subscriptionError" | K4: =IFERROR(IF(I4="Open",(E4+D4)/2,H4),H4) -> "services.rtd.subscriptionError" | L4: =IF(AND(I4="Open",G4>0),F4,K4) -> "services.rtd.subscriptionError"
A5: =$A$2&" FM"&LEFT('cont list_bg'!C8,1)&"00"&RIGHT('cont list_bg'!C8,2)&"!" -> I FMU0026! | B5: =RTD("tt.rtd",,"Inst",$B$1,$A5) -> 6628990053936569924 | C5: =MID(RTD("tt.rtd",,$B5,C$2),7,1)&MID(RTD("tt.rtd",,$B5,C$2),11,1) -> U6 | D5: =RTD("tt.rtd",,$B5,D$2) -> "services.rtd.subscriptionError" | E5: =RTD("tt.rtd",,$B5,E$2) -> "services.rtd.subscriptionError" | F5: =RTD("tt.rtd",,$B5,F$2) -> "services.rtd.subscriptionError" | G5: =RTD("tt.rtd",,$B5,G$2) -> "services.rtd.subscriptionError" | H5: =RTD("tt.rtd",,$B5,H$2) -> "services.rtd.subscriptionError" | I5: =RTD("tt.rtd",,$B5,I$2) -> "services.rtd.subscriptionError" | J5: =RTD("tt.rtd",,$B5,J$2) -> "services.rtd.subscriptionError" | K5: =IFERROR(IF(I5="Open",(E5+D5)/2,H5),H5) -> "services.rtd.subscriptionError" | L5: =IF(AND(I5="Open",G5>0),F5,K5) -> "services.rtd.subscriptionError"
A6: =$A$2&" FM"&LEFT('cont list_bg'!C9,1)&"00"&RIGHT('cont list_bg'!C9,2)&"!" -> I FMZ0026! | B6: =RTD("tt.rtd",,"Inst",$B$1,$A6) -> 196073038322495181 | C6: =MID(RTD("tt.rtd",,$B6,C$2),7,1)&MID(RTD("tt.rtd",,$B6,C$2),11,1) -> Z6 | D6: =RTD("tt.rtd",,$B6,D$2) -> "services.rtd.subscriptionError" | E6: =RTD("tt.rtd",,$B6,E$2) -> "services.rtd.subscriptionError" | F6: =RTD("tt.rtd",,$B6,F$2) -> "services.rtd.subscriptionError" | G6: =RTD("tt.rtd",,$B6,G$2) -> "services.rtd.subscriptionError" | H6: =RTD("tt.rtd",,$B6,H$2) -> "services.rtd.subscriptionError" | I6: =RTD("tt.rtd",,$B6,I$2) -> "services.rtd.subscriptionError" | J6: =RTD("tt.rtd",,$B6,J$2) -> "services.rtd.subscriptionError" | K6: =IFERROR(IF(I6="Open",(E6+D6)/2,H6),H6) -> "services.rtd.subscriptionError" | L6: =IF(AND(I6="Open",G6>0),F6,K6) -> "services.rtd.subscriptionError"
A7: =$A$2&" FM"&LEFT('cont list_bg'!C10,1)&"00"&RIGHT('cont list_bg'!C10,2)&"!" -> I FMH0027! | B7: =RTD("tt.rtd",,"Inst",$B$1,$A7) -> 6532810731306051149 | C7: =MID(RTD("tt.rtd",,$B7,C$2),7,1)&MID(RTD("tt.rtd",,$B7,C$2),11,1) -> H7 | D7: =RTD("tt.rtd",,$B7,D$2) -> "services.rtd.subscriptionError" | E7: =RTD("tt.rtd",,$B7,E$2) -> "services.rtd.subscriptionError" | F7: =RTD("tt.rtd",,$B7,F$2) -> "services.rtd.subscriptionError" | G7: =RTD("tt.rtd",,$B7,G$2) -> "services.rtd.subscriptionError" | H7: =RTD("tt.rtd",,$B7,H$2) -> "services.rtd.subscriptionError" | I7: =RTD("tt.rtd",,$B7,I$2) -> "services.rtd.subscriptionError" | J7: =RTD("tt.rtd",,$B7,J$2) -> "services.rtd.subscriptionError" | K7: =IFERROR(IF(I7="Open",(E7+D7)/2,H7),H7) -> "services.rtd.subscriptionError" | L7: =IF(AND(I7="Open",G7>0),F7,K7) -> "services.rtd.subscriptionError"
A8: =$A$2&" FM"&LEFT('cont list_bg'!C11,1)&"00"&RIGHT('cont list_bg'!C11,2)&"!" -> I FMM0027! | B8: =RTD("tt.rtd",,"Inst",$B$1,$A8) -> 10290150595504250421 | C8: =MID(RTD("tt.rtd",,$B8,C$2),7,1)&MID(RTD("tt.rtd",,$B8,C$2),11,1) -> M7 | D8: =RTD("tt.rtd",,$B8,D$2) -> "services.rtd.subscriptionError" | E8: =RTD("tt.rtd",,$B8,E$2) -> "services.rtd.subscriptionError" | F8: =RTD("tt.rtd",,$B8,F$2) -> "services.rtd.subscriptionError" | G8: =RTD("tt.rtd",,$B8,G$2) -> "services.rtd.subscriptionError" | H8: =RTD("tt.rtd",,$B8,H$2) -> "services.rtd.subscriptionError" | I8: =RTD("tt.rtd",,$B8,I$2) -> "services.rtd.subscriptionError" | J8: =RTD("tt.rtd",,$B8,J$2) -> "services.rtd.subscriptionError" | K8: =IFERROR(IF(I8="Open",(E8+D8)/2,H8),H8) -> "services.rtd.subscriptionError" | L8: =IF(AND(I8="Open",G8>0),F8,K8) -> "services.rtd.subscriptionError"
A9: =$A$2&" FM"&LEFT('cont list_bg'!C12,1)&"00"&RIGHT('cont list_bg'!C12,2)&"!" -> I FMU0027! | B9: =RTD("tt.rtd",,"Inst",$B$1,$A9) -> 18341350720628559368 | C9: =MID(RTD("tt.rtd",,$B9,C$2),7,1)&MID(RTD("tt.rtd",,$B9,C$2),11,1) -> U7 | D9: =RTD("tt.rtd",,$B9,D$2) -> "services.rtd.subscriptionError" | E9: =RTD("tt.rtd",,$B9,E$2) -> "services.rtd.subscriptionError" | F9: =RTD("tt.rtd",,$B9,F$2) -> "services.rtd.subscriptionError" | G9: =RTD("tt.rtd",,$B9,G$2) -> "services.rtd.subscriptionError" | H9: =RTD("tt.rtd",,$B9,H$2) -> "services.rtd.subscriptionError" | I9: =RTD("tt.rtd",,$B9,I$2) -> "services.rtd.subscriptionError" | J9: =RTD("tt.rtd",,$B9,J$2) -> "services.rtd.subscriptionError" | K9: =IFERROR(IF(I9="Open",(E9+D9)/2,H9),H9) -> "services.rtd.subscriptionError" | L9: =IF(AND(I9="Open",G9>0),F9,K9) -> "services.rtd.subscriptionError"
A10: =$A$2&" FM"&LEFT('cont list_bg'!C13,1)&"00"&RIGHT('cont list_bg'!C13,2)&"!" -> I FMZ0027! | B10: =RTD("tt.rtd",,"Inst",$B$1,$A10) -> 17244622560953637946 | C10: =MID(RTD("tt.rtd",,$B10,C$2),7,1)&MID(RTD("tt.rtd",,$B10,C$2),11,1) -> Z7 | D10: =RTD("tt.rtd",,$B10,D$2) -> "services.rtd.subscriptionError" | E10: =RTD("tt.rtd",,$B10,E$2) -> "services.rtd.subscriptionError" | F10: =RTD("tt.rtd",,$B10,F$2) -> "services.rtd.subscriptionError" | G10: =RTD("tt.rtd",,$B10,G$2) -> "services.rtd.subscriptionError" | H10: =RTD("tt.rtd",,$B10,H$2) -> "services.rtd.subscriptionError" | I10: =RTD("tt.rtd",,$B10,I$2) -> "services.rtd.subscriptionError" | J10: =RTD("tt.rtd",,$B10,J$2) -> "services.rtd.subscriptionError" | K10: =IFERROR(IF(I10="Open",(E10+D10)/2,H10),H10) -> "services.rtd.subscriptionError" | L10: =IF(AND(I10="Open",G10>0),F10,K10) -> "services.rtd.subscriptionError"
A11: =$A$2&" FM"&LEFT('cont list_bg'!C14,1)&"00"&RIGHT('cont list_bg'!C14,2)&"!" -> I FMH0028! | B11: =RTD("tt.rtd",,"Inst",$B$1,$A11) -> 6159411209048528655 | C11: =MID(RTD("tt.rtd",,$B11,C$2),7,1)&MID(RTD("tt.rtd",,$B11,C$2),11,1) -> H8 | D11: =RTD("tt.rtd",,$B11,D$2) -> "services.rtd.subscriptionError" | E11: =RTD("tt.rtd",,$B11,E$2) -> "services.rtd.subscriptionError" | F11: =RTD("tt.rtd",,$B11,F$2) -> "services.rtd.subscriptionError" | G11: =RTD("tt.rtd",,$B11,G$2) -> "services.rtd.subscriptionError" | H11: =RTD("tt.rtd",,$B11,H$2) -> "services.rtd.subscriptionError" | I11: =RTD("tt.rtd",,$B11,I$2) -> "services.rtd.subscriptionError" | J11: =RTD("tt.rtd",,$B11,J$2) -> "services.rtd.subscriptionError" | K11: =IFERROR(IF(I11="Open",(E11+D11)/2,H11),H11) -> "services.rtd.subscriptionError" | L11: =IF(AND(I11="Open",G11>0),F11,K11) -> "services.rtd.subscriptionError"
A12: =$A$2&" FM"&LEFT('cont list_bg'!C15,1)&"00"&RIGHT('cont list_bg'!C15,2)&"!" -> I FMM0028! | B12: =RTD("tt.rtd",,"Inst",$B$1,$A12) -> 16203147123713749534 | C12: =MID(RTD("tt.rtd",,$B12,C$2),7,1)&MID(RTD("tt.rtd",,$B12,C$2),11,1) -> M8 | D12: =RTD("tt.rtd",,$B12,D$2) -> "services.rtd.subscriptionError" | E12: =RTD("tt.rtd",,$B12,E$2) -> "services.rtd.subscriptionError" | F12: =RTD("tt.rtd",,$B12,F$2) -> "services.rtd.subscriptionError" | G12: =RTD("tt.rtd",,$B12,G$2) -> "services.rtd.subscriptionError" | H12: =RTD("tt.rtd",,$B12,H$2) -> "services.rtd.subscriptionError" | I12: =RTD("tt.rtd",,$B12,I$2) -> "services.rtd.subscriptionError" | J12: =RTD("tt.rtd",,$B12,J$2) -> "services.rtd.subscriptionError" | K12: =IFERROR(IF(I12="Open",(E12+D12)/2,H12),H12) -> "services.rtd.subscriptionError" | L12: =IF(AND(I12="Open",G12>0),F12,K12) -> "services.rtd.subscriptionError"
A13: =$A$2&" FM"&LEFT('cont list_bg'!C16,1)&"00"&RIGHT('cont list_bg'!C16,2)&"!" -> I FMU0028! | B13: =RTD("tt.rtd",,"Inst",$B$1,$A13) -> 13181973989553924789 | C13: =MID(RTD("tt.rtd",,$B13,C$2),7,1)&MID(RTD("tt.rtd",,$B13,C$2),11,1) -> U8 | D13: =RTD("tt.rtd",,$B13,D$2) -> "services.rtd.subscriptionError" | E13: =RTD("tt.rtd",,$B13,E$2) -> "services.rtd.subscriptionError" | F13: =RTD("tt.rtd",,$B13,F$2) -> "services.rtd.subscriptionError" | G13: =RTD("tt.rtd",,$B13,G$2) -> "services.rtd.subscriptionError" | H13: =RTD("tt.rtd",,$B13,H$2) -> "services.rtd.subscriptionError" | I13: =RTD("tt.rtd",,$B13,I$2) -> "services.rtd.subscriptionError" | J13: =RTD("tt.rtd",,$B13,J$2) -> "services.rtd.subscriptionError" | K13: =IFERROR(IF(I13="Open",(E13+D13)/2,H13),H13) -> "services.rtd.subscriptionError" | L13: =IF(AND(I13="Open",G13>0),F13,K13) -> "services.rtd.subscriptionError"
A14: =$A$2&" FM"&LEFT('cont list_bg'!C17,1)&"00"&RIGHT('cont list_bg'!C17,2)&"!" -> I FMZ0028! | B14: =RTD("tt.rtd",,"Inst",$B$1,$A14) -> 6189133329181631919 | C14: =MID(RTD("tt.rtd",,$B14,C$2),7,1)&MID(RTD("tt.rtd",,$B14,C$2),11,1) -> Z8 | D14: =RTD("tt.rtd",,$B14,D$2) -> "services.rtd.subscriptionError" | E14: =RTD("tt.rtd",,$B14,E$2) -> "services.rtd.subscriptionError" | F14: =RTD("tt.rtd",,$B14,F$2) -> "services.rtd.subscriptionError" | G14: =RTD("tt.rtd",,$B14,G$2) -> "services.rtd.subscriptionError" | H14: =RTD("tt.rtd",,$B14,H$2) -> "services.rtd.subscriptionError" | I14: =RTD("tt.rtd",,$B14,I$2) -> "services.rtd.subscriptionError" | J14: =RTD("tt.rtd",,$B14,J$2) -> "services.rtd.subscriptionError" | K14: =IFERROR(IF(I14="Open",(E14+D14)/2,H14),H14) -> "services.rtd.subscriptionError" | L14: =IF(AND(I14="Open",G14>0),F14,K14) -> "services.rtd.subscriptionError"
A15: =$A$2&" FM"&LEFT('cont list_bg'!C18,1)&"00"&RIGHT('cont list_bg'!C18,2)&"!" -> I FMH0029! | B15: =RTD("tt.rtd",,"Inst",$B$1,$A15) -> 1972877616990500330 | C15: =MID(RTD("tt.rtd",,$B15,C$2),7,1)&MID(RTD("tt.rtd",,$B15,C$2),11,1) -> H9 | D15: =RTD("tt.rtd",,$B15,D$2) -> "services.rtd.subscriptionError" | E15: =RTD("tt.rtd",,$B15,E$2) -> "services.rtd.subscriptionError" | F15: =RTD("tt.rtd",,$B15,F$2) -> "services.rtd.subscriptionError" | G15: =RTD("tt.rtd",,$B15,G$2) -> "services.rtd.subscriptionError" | H15: =RTD("tt.rtd",,$B15,H$2) -> "services.rtd.subscriptionError" | I15: =RTD("tt.rtd",,$B15,I$2) -> "services.rtd.subscriptionError" | J15: =RTD("tt.rtd",,$B15,J$2) -> "services.rtd.subscriptionError" | K15: =IFERROR(IF(I15="Open",(E15+D15)/2,H15),H15) -> "services.rtd.subscriptionError" | L15: =IF(AND(I15="Open",G15>0),F15,K15) -> "services.rtd.subscriptionError"
... A26: =$A$2&" FM"&LEFT('cont list_bg'!C29,1)&"00"&RIGHT('cont list_bg'!C29,2)&"!" -> I FMZ0031! | B26: =RTD("tt.rtd",,"Inst",$B$1,$A26) -> 11911434118028235803 | C26: =MID(RTD("tt.rtd",,$B26,C$2),7,1)&MID(RTD("tt.rtd",,$B26,C$2),11,1) -> Z1 | D26: =RTD("tt.rtd",,$B26,D$2) -> "services.rtd.subscriptionError" | E26: =RTD("tt.rtd",,$B26,E$2) -> "services.rtd.subscriptionError" | F26: =RTD("tt.rtd",,$B26,F$2) -> "services.rtd.subscriptionError" | G26: =RTD("tt.rtd",,$B26,G$2) -> "services.rtd.subscriptionError" | H26: =RTD("tt.rtd",,$B26,H$2) -> "services.rtd.subscriptionError" | I26: =RTD("tt.rtd",,$B26,I$2) -> "services.rtd.subscriptionError" | J26: =RTD("tt.rtd",,$B26,J$2) -> "services.rtd.subscriptionError" | K26: =IFERROR(IF(I26="Open",(E26+D26)/2,H26),H26) -> "services.rtd.subscriptionError" | L26: =IF(AND(I26="Open",G26>0),F26,K26) -> "services.rtd.subscriptionError"

Sheet SO3
A1: SO3 | B1: ICE_L
A2: SO3 | B2: instrument ID | C2: Name | D2: Ask | E2: Bid | F2: Last | G2: CTQ | H2: Settle | I2: Status | J2: CTQ | K2: Mid | L2: Last
A3: =$A$2&" FM"&LEFT('cont list_bg'!G6,1)&"00"&RIGHT('cont list_bg'!G6,2)&"!" -> SO3 FMH0026! | B3: =RTD("tt.rtd",,"Inst",$B$1,$A3) -> 1000973058687712295 | C3: =MID(RTD("tt.rtd",,$B3,C$2),7,1)&MID(RTD("tt.rtd",,$B3,C$2),11,1) -> H6 | D3: =RTD("tt.rtd",,$B3,D$2) -> "services.rtd.subscriptionError" | E3: =RTD("tt.rtd",,$B3,E$2) -> "services.rtd.subscriptionError" | F3: =RTD("tt.rtd",,$B3,F$2) -> "services.rtd.subscriptionError" | G3: =RTD("tt.rtd",,$B3,G$2) -> "services.rtd.subscriptionError" | H3: =RTD("tt.rtd",,$B3,H$2) -> "services.rtd.subscriptionError" | I3: =RTD("tt.rtd",,$B3,I$2) -> "services.rtd.subscriptionError" | J3: =RTD("tt.rtd",,$B3,J$2) -> "services.rtd.subscriptionError" | K3: =IFERROR(IF(I3="Open",(E3+D3)/2,H3),H3) -> "services.rtd.subscriptionError" | L3: =IF(AND(I3="Open",G3>0),F3,K3) -> "services.rtd.subscriptionError"
A4: =$A$2&" FM"&LEFT('cont list_bg'!G7,1)&"00"&RIGHT('cont list_bg'!G7,2)&"!" -> SO3 FMM0026! | B4: =RTD("tt.rtd",,"Inst",$B$1,$A4) -> 17388498933531365606 | C4: =MID(RTD("tt.rtd",,$B4,C$2),7,1)&MID(RTD("tt.rtd",,$B4,C$2),11,1) -> M6 | D4: =RTD("tt.rtd",,$B4,D$2) -> "services.rtd.subscriptionError" | E4: =RTD("tt.rtd",,$B4,E$2) -> "services.rtd.subscriptionError" | F4: =RTD("tt.rtd",,$B4,F$2) -> "services.rtd.subscriptionError" | G4: =RTD("tt.rtd",,$B4,G$2) -> "services.rtd.subscriptionError" | H4: =RTD("tt.rtd",,$B4,H$2) -> "services.rtd.subscriptionError" | I4: =RTD("tt.rtd",,$B4,I$2) -> "services.rtd.subscriptionError" | J4: =RTD("tt.rtd",,$B4,J$2) -> "services.rtd.subscriptionError" | K4: =IFERROR(IF(I4="Open",(E4+D4)/2,H4),H4) -> "services.rtd.subscriptionError" | L4: =IF(AND(I4="Open",G4>0),F4,K4) -> "services.rtd.subscriptionError"
A5: =$A$2&" FM"&LEFT('cont list_bg'!G8,1)&"00"&RIGHT('cont list_bg'!G8,2)&"!" -> SO3 FMU0026! | B5: =RTD("tt.rtd",,"Inst",$B$1,$A5) -> 14330867541177216896 | C5: =MID(RTD("tt.rtd",,$B5,C$2),7,1)&MID(RTD("tt.rtd",,$B5,C$2),11,1) -> U6 | D5: =RTD("tt.rtd",,$B5,D$2) -> "services.rtd.subscriptionError" | E5: =RTD("tt.rtd",,$B5,E$2) -> "services.rtd.subscriptionError" | F5: =RTD("tt.rtd",,$B5,F$2) -> "services.rtd.subscriptionError" | G5: =RTD("tt.rtd",,$B5,G$2) -> "services.rtd.subscriptionError" | H5: =RTD("tt.rtd",,$B5,H$2) -> "services.rtd.subscriptionError" | I5: =RTD("tt.rtd",,$B5,I$2) -> "services.rtd.subscriptionError" | J5: =RTD("tt.rtd",,$B5,J$2) -> "services.rtd.subscriptionError" | K5: =IFERROR(IF(I5="Open",(E5+D5)/2,H5),H5) -> "services.rtd.subscriptionError" | L5: =IF(AND(I5="Open",G5>0),F5,K5) -> "services.rtd.subscriptionError"
A6: =$A$2&" FM"&LEFT('cont list_bg'!G9,1)&"00"&RIGHT('cont list_bg'!G9,2)&"!" -> SO3 FMZ0026! | B6: =RTD("tt.rtd",,"Inst",$B$1,$A6) -> 2929215027186538641 | C6: =MID(RTD("tt.rtd",,$B6,C$2),7,1)&MID(RTD("tt.rtd",,$B6,C$2),11,1) -> Z6 | D6: =RTD("tt.rtd",,$B6,D$2) -> "services.rtd.subscriptionError" | E6: =RTD("tt.rtd",,$B6,E$2) -> "services.rtd.subscriptionError" | F6: =RTD("tt.rtd",,$B6,F$2) -> "services.rtd.subscriptionError" | G6: =RTD("tt.rtd",,$B6,G$2) -> "services.rtd.subscriptionError" | H6: =RTD("tt.rtd",,$B6,H$2) -> "services.rtd.subscriptionError" | I6: =RTD("tt.rtd",,$B6,I$2) -> "services.rtd.subscriptionError" | J6: =RTD("tt.rtd",,$B6,J$2) -> "services.rtd.subscriptionError" | K6: =IFERROR(IF(I6="Open",(E6+D6)/2,H6),H6) -> "services.rtd.subscriptionError" | L6: =IF(AND(I6="Open",G6>0),F6,K6) -> "services.rtd.subscriptionError"
A7: =$A$2&" FM"&LEFT('cont list_bg'!G10,1)&"00"&RIGHT('cont list_bg'!G10,2)&"!" -> SO3 FMH0027! | B7: =RTD("tt.rtd",,"Inst",$B$1,$A7) -> 12777480240935901350 | C7: =MID(RTD("tt.rtd",,$B7,C$2),7,1)&MID(RTD("tt.rtd",,$B7,C$2),11,1) -> H7 | D7: =RTD("tt.rtd",,$B7,D$2) -> "services.rtd.subscriptionError" | E7: =RTD("tt.rtd",,$B7,E$2) -> "services.rtd.subscriptionError" | F7: =RTD("tt.rtd",,$B7,F$2) -> "services.rtd.subscriptionError" | G7: =RTD("tt.rtd",,$B7,G$2) -> "services.rtd.subscriptionError" | H7: =RTD("tt.rtd",,$B7,H$2) -> "services.rtd.subscriptionError" | I7: =RTD("tt.rtd",,$B7,I$2) -> "services.rtd.subscriptionError" | J7: =RTD("tt.rtd",,$B7,J$2) -> "services.rtd.subscriptionError" | K7: =IFERROR(IF(I7="Open",(E7+D7)/2,H7),H7) -> "services.rtd.subscriptionError" | L7: =IF(AND(I7="Open",G7>0),F7,K7) -> "services.rtd.subscriptionError"
A8: =$A$2&" FM"&LEFT('cont list_bg'!G11,1)&"00"&RIGHT('cont list_bg'!G11,2)&"!" -> SO3 FMM0027! | B8: =RTD("tt.rtd",,"Inst",$B$1,$A8) -> 17489439929274896309 | C8: =MID(RTD("tt.rtd",,$B8,C$2),7,1)&MID(RTD("tt.rtd",,$B8,C$2),11,1) -> M7 | D8: =RTD("tt.rtd",,$B8,D$2) -> "services.rtd.subscriptionError" | E8: =RTD("tt.rtd",,$B8,E$2) -> "services.rtd.subscriptionError" | F8: =RTD("tt.rtd",,$B8,F$2) -> "services.rtd.subscriptionError" | G8: =RTD("tt.rtd",,$B8,G$2) -> "services.rtd.subscriptionError" | H8: =RTD("tt.rtd",,$B8,H$2) -> "services.rtd.subscriptionError" | I8: =RTD("tt.rtd",,$B8,I$2) -> "services.rtd.subscriptionError" | J8: =RTD("tt.rtd",,$B8,J$2) -> "services.rtd.subscriptionError" | K8: =IFERROR(IF(I8="Open",(E8+D8)/2,H8),H8) -> "services.rtd.subscriptionError" | L8: =IF(AND(I8="Open",G8>0),F8,K8) -> "services.rtd.subscriptionError"
A9: =$A$2&" FM"&LEFT('cont list_bg'!G12,1)&"00"&RIGHT('cont list_bg'!G12,2)&"!" -> SO3 FMU0027! | B9: =RTD("tt.rtd",,"Inst",$B$1,$A9) -> 13124315370012665646 | C9: =MID(RTD("tt.rtd",,$B9,C$2),7,1)&MID(RTD("tt.rtd",,$B9,C$2),11,1) -> U7 | D9: =RTD("tt.rtd",,$B9,D$2) -> "services.rtd.subscriptionError" | E9: =RTD("tt.rtd",,$B9,E$2) -> "services.rtd.subscriptionError" | F9: =RTD("tt.rtd",,$B9,F$2) -> "services.rtd.subscriptionError" | G9: =RTD("tt.rtd",,$B9,G$2) -> "services.rtd.subscriptionError" | H9: =RTD("tt.rtd",,$B9,H$2) -> "services.rtd.subscriptionError" | I9: =RTD("tt.rtd",,$B9,I$2) -> "services.rtd.subscriptionError" | J9: =RTD("tt.rtd",,$B9,J$2) -> "services.rtd.subscriptionError" | K9: =IFERROR(IF(I9="Open",(E9+D9)/2,H9),H9) -> "services.rtd.subscriptionError" | L9: =IF(AND(I9="Open",G9>0),F9,K9) -> "services.rtd.subscriptionError"
A10: =$A$2&" FM"&LEFT('cont list_bg'!G13,1)&"00"&RIGHT('cont list_bg'!G13,2)&"!" -> SO3 FMZ0027! | B10: =RTD("tt.rtd",,"Inst",$B$1,$A10) -> 6883681751251454284 | C10: =MID(RTD("tt.rtd",,$B10,C$2),7,1)&MID(RTD("tt.rtd",,$B10,C$2),11,1) -> Z7 | D10: =RTD("tt.rtd",,$B10,D$2) -> "services.rtd.subscriptionError" | E10: =RTD("tt.rtd",,$B10,E$2) -> "services.rtd.subscriptionError" | F10: =RTD("tt.rtd",,$B10,F$2) -> "services.rtd.subscriptionError" | G10: =RTD("tt.rtd",,$B10,G$2) -> "services.rtd.subscriptionError" | H10: =RTD("tt.rtd",,$B10,H$2) -> "services.rtd.subscriptionError" | I10: =RTD("tt.rtd",,$B10,I$2) -> "services.rtd.subscriptionError" | J10: =RTD("tt.rtd",,$B10,J$2) -> "services.rtd.subscriptionError" | K10: =IFERROR(IF(I10="Open",(E10+D10)/2,H10),H10) -> "services.rtd.subscriptionError" | L10: =IF(AND(I10="Open",G10>0),F10,K10) -> "services.rtd.subscriptionError"
A11: =$A$2&" FM"&LEFT('cont list_bg'!G14,1)&"00"&RIGHT('cont list_bg'!G14,2)&"!" -> SO3 FMH0028! | B11: =RTD("tt.rtd",,"Inst",$B$1,$A11) -> 4771138968527992296 | C11: =MID(RTD("tt.rtd",,$B11,C$2),7,1)&MID(RTD("tt.rtd",,$B11,C$2),11,1) -> H8 | D11: =RTD("tt.rtd",,$B11,D$2) -> "services.rtd.subscriptionError" | E11: =RTD("tt.rtd",,$B11,E$2) -> "services.rtd.subscriptionError" | F11: =RTD("tt.rtd",,$B11,F$2) -> "services.rtd.subscriptionError" | G11: =RTD("tt.rtd",,$B11,G$2) -> "services.rtd.subscriptionError" | H11: =RTD("tt.rtd",,$B11,H$2) -> "services.rtd.subscriptionError" | I11: =RTD("tt.rtd",,$B11,I$2) -> "services.rtd.subscriptionError" | J11: =RTD("tt.rtd",,$B11,J$2) -> "services.rtd.subscriptionError" | K11: =IFERROR(IF(I11="Open",(E11+D11)/2,H11),H11) -> "services.rtd.subscriptionError" | L11: =IF(AND(I11="Open",G11>0),F11,K11) -> "services.rtd.subscriptionError"
A12: =$A$2&" FM"&LEFT('cont list_bg'!G15,1)&"00"&RIGHT('cont list_bg'!G15,2)&"!" -> SO3 FMM0028! | B12: =RTD("tt.rtd",,"Inst",$B$1,$A12) -> 1778338967582843813 | C12: =MID(RTD("tt.rtd",,$B12,C$2),7,1)&MID(RTD("tt.rtd",,$B12,C$2),11,1) -> M8 | D12: =RTD("tt.rtd",,$B12,D$2) -> "services.rtd.subscriptionError" | E12: =RTD("tt.rtd",,$B12,E$2) -> "services.rtd.subscriptionError" | F12: =RTD("tt.rtd",,$B12,F$2) -> "services.rtd.subscriptionError" | G12: =RTD("tt.rtd",,$B12,G$2) -> "services.rtd.subscriptionError" | H12: =RTD("tt.rtd",,$B12,H$2) -> "services.rtd.subscriptionError" | I12: =RTD("tt.rtd",,$B12,I$2) -> "services.rtd.subscriptionError" | J12: =RTD("tt.rtd",,$B12,J$2) -> "services.rtd.subscriptionError" | K12: =IFERROR(IF(I12="Open",(E12+D12)/2,H12),H12) -> "services.rtd.subscriptionError" | L12: =IF(AND(I12="Open",G12>0),F12,K12) -> "services.rtd.subscriptionError"
A13: =$A$2&" FM"&LEFT('cont list_bg'!G16,1)&"00"&RIGHT('cont list_bg'!G16,2)&"!" -> SO3 FMU0028! | B13: =RTD("tt.rtd",,"Inst",$B$1,$A13) -> 13553073652848841644 | C13: =MID(RTD("tt.rtd",,$B13,C$2),7,1)&MID(RTD("tt.rtd",,$B13,C$2),11,1) -> U8 | D13: =RTD("tt.rtd",,$B13,D$2) -> "services.rtd.subscriptionError" | E13: =RTD("tt.rtd",,$B13,E$2) -> "services.rtd.subscriptionError" | F13: =RTD("tt.rtd",,$B13,F$2) -> "services.rtd.subscriptionError" | G13: =RTD("tt.rtd",,$B13,G$2) -> "services.rtd.subscriptionError" | H13: =RTD("tt.rtd",,$B13,H$2) -> "services.rtd.subscriptionError" | I13: =RTD("tt.rtd",,$B13,I$2) -> "services.rtd.subscriptionError" | J13: =RTD("tt.rtd",,$B13,J$2) -> "services.rtd.subscriptionError" | K13: =IFERROR(IF(I13="Open",(E13+D13)/2,H13),H13) -> "services.rtd.subscriptionError" | L13: =IF(AND(I13="Open",G13>0),F13,K13) -> "services.rtd.subscriptionError"
A14: =$A$2&" FM"&LEFT('cont list_bg'!G17,1)&"00"&RIGHT('cont list_bg'!G17,2)&"!" -> SO3 FMZ0028! | B14: =RTD("tt.rtd",,"Inst",$B$1,$A14) -> 12802673068039550141 | C14: =MID(RTD("tt.rtd",,$B14,C$2),7,1)&MID(RTD("tt.rtd",,$B14,C$2),11,1) -> Z8 | D14: =RTD("tt.rtd",,$B14,D$2) -> "services.rtd.subscriptionError" | E14: =RTD("tt.rtd",,$B14,E$2) -> "services.rtd.subscriptionError" | F14: =RTD("tt.rtd",,$B14,F$2) -> "services.rtd.subscriptionError" | G14: =RTD("tt.rtd",,$B14,G$2) -> "services.rtd.subscriptionError" | H14: =RTD("tt.rtd",,$B14,H$2) -> "services.rtd.subscriptionError" | I14: =RTD("tt.rtd",,$B14,I$2) -> "services.rtd.subscriptionError" | J14: =RTD("tt.rtd",,$B14,J$2) -> "services.rtd.subscriptionError" | K14: =IFERROR(IF(I14="Open",(E14+D14)/2,H14),H14) -> "services.rtd.subscriptionError" | L14: =IF(AND(I14="Open",G14>0),F14,K14) -> "services.rtd.subscriptionError"
... A27: =$A$2&" FM"&LEFT('cont list_bg'!G30,1)&"00"&RIGHT('cont list_bg'!G30,2)&"!" -> SO3 FMH0032! | B27: =RTD("tt.rtd",,"Inst",$B$1,$A27) -> 1916532763064230074 | C27: =MID(RTD("tt.rtd",,$B27,C$2),7,1)&MID(RTD("tt.rtd",,$B27,C$2),11,1) -> H2 | D27: =RTD("tt.rtd",,$B27,D$2) -> 95.295 | E27: =RTD("tt.rtd",,$B27,E$2) -> 95.235 | F27: =RTD("tt.rtd",,$B27,F$2) | G27: =RTD("tt.rtd",,$B27,G$2) -> 0 | H27: =RTD("tt.rtd",,$B27,H$2) -> 95.215 | I27: =RTD("tt.rtd",,$B27,I$2) -> Open | J27: =RTD("tt.rtd",,$B27,J$2) -> 0 | K27: =IFERROR(IF(I27="Open",(E27+D27)/2,H27),H27) -> 95.265 | L27: =IF(AND(I27="Open",G27>0),F27,K27) -> 95.265

Sheet SA3
A1: SA3 | B1: ICE_L
A2: SA3 | B2: instrument ID | C2: Name | D2: Ask | E2: Bid | F2: Last | G2: CTQ | H2: Settle | I2: Status | J2: CTQ | K2: Mid | L2: Last
A3: =$A$2&" FM"&LEFT('cont list_bg'!G6,1)&"00"&RIGHT('cont list_bg'!G6,2)&"!" -> SA3 FMH0026! | B3: =RTD("tt.rtd",,"Inst",$B$1,$A3) -> 14714678855879803828 | C3: =MID(RTD("tt.rtd",,$B3,C$2),7,1)&MID(RTD("tt.rtd",,$B3,C$2),11,1) -> H6 | D3: =RTD("tt.rtd",,$B3,D$2) -> "services.rtd.subscriptionError" | E3: =RTD("tt.rtd",,$B3,E$2) -> "services.rtd.subscriptionError" | F3: =RTD("tt.rtd",,$B3,F$2) -> "services.rtd.subscriptionError" | G3: =RTD("tt.rtd",,$B3,G$2) -> "services.rtd.subscriptionError" | H3: =RTD("tt.rtd",,$B3,H$2) -> "services.rtd.subscriptionError" | I3: =RTD("tt.rtd",,$B3,I$2) -> "services.rtd.subscriptionError" | J3: =RTD("tt.rtd",,$B3,J$2) -> "services.rtd.subscriptionError" | K3: =IFERROR(IF(I3="Open",(E3+D3)/2,H3),H3) -> "services.rtd.subscriptionError" | L3: =IF(AND(I3="Open",G3>0),F3,K3) -> "services.rtd.subscriptionError"
A4: =$A$2&" FM"&LEFT('cont list_bg'!G7,1)&"00"&RIGHT('cont list_bg'!G7,2)&"!" -> SA3 FMM0026! | B4: =RTD("tt.rtd",,"Inst",$B$1,$A4) -> 6777292727603905167 | C4: =MID(RTD("tt.rtd",,$B4,C$2),7,1)&MID(RTD("tt.rtd",,$B4,C$2),11,1) -> M6 | D4: =RTD("tt.rtd",,$B4,D$2) -> "services.rtd.subscriptionError" | E4: =RTD("tt.rtd",,$B4,E$2) -> "services.rtd.subscriptionError" | F4: =RTD("tt.rtd",,$B4,F$2) -> "services.rtd.subscriptionError" | G4: =RTD("tt.rtd",,$B4,G$2) -> "services.rtd.subscriptionError" | H4: =RTD("tt.rtd",,$B4,H$2) -> "services.rtd.subscriptionError" | I4: =RTD("tt.rtd",,$B4,I$2) -> "services.rtd.subscriptionError" | J4: =RTD("tt.rtd",,$B4,J$2) -> "services.rtd.subscriptionError" | K4: =IFERROR(IF(I4="Open",(E4+D4)/2,H4),H4) -> "services.rtd.subscriptionError" | L4: =IF(AND(I4="Open",G4>0),F4,K4) -> "services.rtd.subscriptionError"
A5: =$A$2&" FM"&LEFT('cont list_bg'!G8,1)&"00"&RIGHT('cont list_bg'!G8,2)&"!" -> SA3 FMU0026! | B5: =RTD("tt.rtd",,"Inst",$B$1,$A5) -> 10152022727750786343 | C5: =MID(RTD("tt.rtd",,$B5,C$2),7,1)&MID(RTD("tt.rtd",,$B5,C$2),11,1) -> U6 | D5: =RTD("tt.rtd",,$B5,D$2) -> "services.rtd.subscriptionError" | E5: =RTD("tt.rtd",,$B5,E$2) -> "services.rtd.subscriptionError" | F5: =RTD("tt.rtd",,$B5,F$2) -> "services.rtd.subscriptionError" | G5: =RTD("tt.rtd",,$B5,G$2) -> "services.rtd.subscriptionError" | H5: =RTD("tt.rtd",,$B5,H$2) -> "services.rtd.subscriptionError" | I5: =RTD("tt.rtd",,$B5,I$2) -> "services.rtd.subscriptionError" | J5: =RTD("tt.rtd",,$B5,J$2) -> "services.rtd.subscriptionError" | K5: =IFERROR(IF(I5="Open",(E5+D5)/2,H5),H5) -> "services.rtd.subscriptionError" | L5: =IF(AND(I5="Open",G5>0),F5,K5) -> "services.rtd.subscriptionError"
A6: =$A$2&" FM"&LEFT('cont list_bg'!G9,1)&"00"&RIGHT('cont list_bg'!G9,2)&"!" -> SA3 FMZ0026! | B6: =RTD("tt.rtd",,"Inst",$B$1,$A6) -> 6914531881671971328 | C6: =MID(RTD("tt.rtd",,$B6,C$2),7,1)&MID(RTD("tt.rtd",,$B6,C$2),11,1) -> Z6 | D6: =RTD("tt.rtd",,$B6,D$2) -> "services.rtd.subscriptionError" | E6: =RTD("tt.rtd",,$B6,E$2) -> "services.rtd.subscriptionError" | F6: =RTD("tt.rtd",,$B6,F$2) -> "services.rtd.subscriptionError" | G6: =RTD("tt.rtd",,$B6,G$2) -> "services.rtd.subscriptionError" | H6: =RTD("tt.rtd",,$B6,H$2) -> "services.rtd.subscriptionError" | I6: =RTD("tt.rtd",,$B6,I$2) -> "services.rtd.subscriptionError" | J6: =RTD("tt.rtd",,$B6,J$2) -> "services.rtd.subscriptionError" | K6: =IFERROR(IF(I6="Open",(E6+D6)/2,H6),H6) -> "services.rtd.subscriptionError" | L6: =IF(AND(I6="Open",G6>0),F6,K6) -> "services.rtd.subscriptionError"
A7: =$A$2&" FM"&LEFT('cont list_bg'!G10,1)&"00"&RIGHT('cont list_bg'!G10,2)&"!" -> SA3 FMH0027! | B7: =RTD("tt.rtd",,"Inst",$B$1,$A7) -> 5619891302845554146 | C7: =MID(RTD("tt.rtd",,$B7,C$2),7,1)&MID(RTD("tt.rtd",,$B7,C$2),11,1) -> H7 | D7: =RTD("tt.rtd",,$B7,D$2) -> "services.rtd.subscriptionError" | E7: =RTD("tt.rtd",,$B7,E$2) -> "services.rtd.subscriptionError" | F7: =RTD("tt.rtd",,$B7,F$2) -> "services.rtd.subscriptionError" | G7: =RTD("tt.rtd",,$B7,G$2) -> "services.rtd.subscriptionError" | H7: =RTD("tt.rtd",,$B7,H$2) -> "services.rtd.subscriptionError" | I7: =RTD("tt.rtd",,$B7,I$2) -> "services.rtd.subscriptionError" | J7: =RTD("tt.rtd",,$B7,J$2) -> "services.rtd.subscriptionError" | K7: =IFERROR(IF(I7="Open",(E7+D7)/2,H7),H7) -> "services.rtd.subscriptionError" | L7: =IF(AND(I7="Open",G7>0),F7,K7) -> "services.rtd.subscriptionError"
A8: =$A$2&" FM"&LEFT('cont list_bg'!G11,1)&"00"&RIGHT('cont list_bg'!G11,2)&"!" -> SA3 FMM0027! | B8: =RTD("tt.rtd",,"Inst",$B$1,$A8) -> 11935287284762367596 | C8: =MID(RTD("tt.rtd",,$B8,C$2),7,1)&MID(RTD("tt.rtd",,$B8,C$2),11,1) -> M7 | D8: =RTD("tt.rtd",,$B8,D$2) -> "services.rtd.subscriptionError" | E8: =RTD("tt.rtd",,$B8,E$2) -> "services.rtd.subscriptionError" | F8: =RTD("tt.rtd",,$B8,F$2) -> "services.rtd.subscriptionError" | G8: =RTD("tt.rtd",,$B8,G$2) -> "services.rtd.subscriptionError" | H8: =RTD("tt.rtd",,$B8,H$2) -> "services.rtd.subscriptionError" | I8: =RTD("tt.rtd",,$B8,I$2) -> "services.rtd.subscriptionError" | J8: =RTD("tt.rtd",,$B8,J$2) -> "services.rtd.subscriptionError" | K8: =IFERROR(IF(I8="Open",(E8+D8)/2,H8),H8) -> "services.rtd.subscriptionError" | L8: =IF(AND(I8="Open",G8>0),F8,K8) -> "services.rtd.subscriptionError"
A9: =$A$2&" FM"&LEFT('cont list_bg'!G12,1)&"00"&RIGHT('cont list_bg'!G12,2)&"!" -> SA3 FMU0027! | B9: =RTD("tt.rtd",,"Inst",$B$1,$A9) -> 3973483485124835681 | C9: =MID(RTD("tt.rtd",,$B9,C$2),7,1)&MID(RTD("tt.rtd",,$B9,C$2),11,1) -> U7 | D9: =RTD("tt.rtd",,$B9,D$2) -> "services.rtd.subscriptionError" | E9: =RTD("tt.rtd",,$B9,E$2) -> "services.rtd.subscriptionError" | F9: =RTD("tt.rtd",,$B9,F$2) -> "services.rtd.subscriptionError" | G9: =RTD("tt.rtd",,$B9,G$2) -> "services.rtd.subscriptionError" | H9: =RTD("tt.rtd",,$B9,H$2) -> "services.rtd.subscriptionError" | I9: =RTD("tt.rtd",,$B9,I$2) -> "services.rtd.subscriptionError" | J9: =RTD("tt.rtd",,$B9,J$2) -> "services.rtd.subscriptionError" | K9: =IFERROR(IF(I9="Open",(E9+D9)/2,H9),H9) -> "services.rtd.subscriptionError" | L9: =IF(AND(I9="Open",G9>0),F9,K9) -> "services.rtd.subscriptionError"
A10: =$A$2&" FM"&LEFT('cont list_bg'!G13,1)&"00"&RIGHT('cont list_bg'!G13,2)&"!" -> SA3 FMZ0027! | B10: =RTD("tt.rtd",,"Inst",$B$1,$A10) -> 12146542221589140494 | C10: =MID(RTD("tt.rtd",,$B10,C$2),7,1)&MID(RTD("tt.rtd",,$B10,C$2),11,1) -> Z7 | D10: =RTD("tt.rtd",,$B10,D$2) -> "services.rtd.subscriptionError" | E10: =RTD("tt.rtd",,$B10,E$2) -> "services.rtd.subscriptionError" | F10: =RTD("tt.rtd",,$B10,F$2) -> "services.rtd.subscriptionError" | G10: =RTD("tt.rtd",,$B10,G$2) -> "services.rtd.subscriptionError" | H10: =RTD("tt.rtd",,$B10,H$2) -> "services.rtd.subscriptionError" | I10: =RTD("tt.rtd",,$B10,I$2) -> "services.rtd.subscriptionError" | J10: =RTD("tt.rtd",,$B10,J$2) -> "services.rtd.subscriptionError" | K10: =IFERROR(IF(I10="Open",(E10+D10)/2,H10),H10) -> "services.rtd.subscriptionError" | L10: =IF(AND(I10="Open",G10>0),F10,K10) -> "services.rtd.subscriptionError"
A11: =$A$2&" FM"&LEFT('cont list_bg'!G14,1)&"00"&RIGHT('cont list_bg'!G14,2)&"!" -> SA3 FMH0028! | B11: =RTD("tt.rtd",,"Inst",$B$1,$A11) -> 6314259765637387886 | C11: =MID(RTD("tt.rtd",,$B11,C$2),7,1)&MID(RTD("tt.rtd",,$B11,C$2),11,1) -> H8 | D11: =RTD("tt.rtd",,$B11,D$2) -> "services.rtd.subscriptionError" | E11: =RTD("tt.rtd",,$B11,E$2) -> "services.rtd.subscriptionError" | F11: =RTD("tt.rtd",,$B11,F$2) -> "services.rtd.subscriptionError" | G11: =RTD("tt.rtd",,$B11,G$2) -> "services.rtd.subscriptionError" | H11: =RTD("tt.rtd",,$B11,H$2) -> "services.rtd.subscriptionError" | I11: =RTD("tt.rtd",,$B11,I$2) -> "services.rtd.subscriptionError" | J11: =RTD("tt.rtd",,$B11,J$2) -> "services.rtd.subscriptionError" | K11: =IFERROR(IF(I11="Open",(E11+D11)/2,H11),H11) -> "services.rtd.subscriptionError" | L11: =IF(AND(I11="Open",G11>0),F11,K11) -> "services.rtd.subscriptionError"
A12: =$A$2&" FM"&LEFT('cont list_bg'!G15,1)&"00"&RIGHT('cont list_bg'!G15,2)&"!" -> SA3 FMM0028! | B12: =RTD("tt.rtd",,"Inst",$B$1,$A12) -> 12197960486633385234 | C12: =MID(RTD("tt.rtd",,$B12,C$2),7,1)&MID(RTD("tt.rtd",,$B12,C$2),11,1) -> M8 | D12: =RTD("tt.rtd",,$B12,D$2) -> "services.rtd.subscriptionError" | E12: =RTD("tt.rtd",,$B12,E$2) -> "services.rtd.subscriptionError" | F12: =RTD("tt.rtd",,$B12,F$2) -> "services.rtd.subscriptionError" | G12: =RTD("tt.rtd",,$B12,G$2) -> "services.rtd.subscriptionError" | H12: =RTD("tt.rtd",,$B12,H$2) -> "services.rtd.subscriptionError" | I12: =RTD("tt.rtd",,$B12,I$2) -> "services.rtd.subscriptionError" | J12: =RTD("tt.rtd",,$B12,J$2) -> "services.rtd.subscriptionError" | K12: =IFERROR(IF(I12="Open",(E12+D12)/2,H12),H12) -> "services.rtd.subscriptionError" | L12: =IF(AND(I12="Open",G12>0),F12,K12) -> "services.rtd.subscriptionError"
A13: =$A$2&" FM"&LEFT('cont list_bg'!G16,1)&"00"&RIGHT('cont list_bg'!G16,2)&"!" -> SA3 FMU0028! | B13: =RTD("tt.rtd",,"Inst",$B$1,$A13) -> 12203053644589187435 | C13: =MID(RTD("tt.rtd",,$B13,C$2),7,1)&MID(RTD("tt.rtd",,$B13,C$2),11,1) -> U8 | D13: =RTD("tt.rtd",,$B13,D$2) -> "services.rtd.subscriptionError" | E13: =RTD("tt.rtd",,$B13,E$2) -> "services.rtd.subscriptionError" | F13: =RTD("tt.rtd",,$B13,F$2) -> "services.rtd.subscriptionError" | G13: =RTD("tt.rtd",,$B13,G$2) -> "services.rtd.subscriptionError" | H13: =RTD("tt.rtd",,$B13,H$2) -> "services.rtd.subscriptionError" | I13: =RTD("tt.rtd",,$B13,I$2) -> "services.rtd.subscriptionError" | J13: =RTD("tt.rtd",,$B13,J$2) -> "services.rtd.subscriptionError" | K13: =IFERROR(IF(I13="Open",(E13+D13)/2,H13),H13) -> "services.rtd.subscriptionError" | L13: =IF(AND(I13="Open",G13>0),F13,K13) -> "services.rtd.subscriptionError"
A14: =$A$2&" FM"&LEFT('cont list_bg'!G17,1)&"00"&RIGHT('cont list_bg'!G17,2)&"!" -> SA3 FMZ0028! | B14: =RTD("tt.rtd",,"Inst",$B$1,$A14) -> 14401575330262518877 | C14: =MID(RTD("tt.rtd",,$B14,C$2),7,1)&MID(RTD("tt.rtd",,$B14,C$2),11,1) -> Z8 | D14: =RTD("tt.rtd",,$B14,D$2) -> "services.rtd.subscriptionError" | E14: =RTD("tt.rtd",,$B14,E$2) -> "services.rtd.subscriptionError" | F14: =RTD("tt.rtd",,$B14,F$2) -> "services.rtd.subscriptionError" | G14: =RTD("tt.rtd",,$B14,G$2) -> "services.rtd.subscriptionError" | H14: =RTD("tt.rtd",,$B14,H$2) -> "services.rtd.subscriptionError" | I14: =RTD("tt.rtd",,$B14,I$2) -> "services.rtd.subscriptionError" | J14: =RTD("tt.rtd",,$B14,J$2) -> "services.rtd.subscriptionError" | K14: =IFERROR(IF(I14="Open",(E14+D14)/2,H14),H14) -> "services.rtd.subscriptionError" | L14: =IF(AND(I14="Open",G14>0),F14,K14) -> "services.rtd.subscriptionError"
... A18: =$A$2&" FM"&LEFT('cont list_bg'!G21,1)&"00"&RIGHT('cont list_bg'!G21,2)&"!" -> SA3 FMZ0029! | B18: =RTD("tt.rtd",,"Inst",$B$1,$A18) -> 18071176284543341830 | C18: =MID(RTD("tt.rtd",,$B18,C$2),7,1)&MID(RTD("tt.rtd",,$B18,C$2),11,1) -> Z9 | D18: =RTD("tt.rtd",,$B18,D$2) -> "services.rtd.subscriptionError" | E18: =RTD("tt.rtd",,$B18,E$2) -> "services.rtd.subscriptionError" | F18: =RTD("tt.rtd",,$B18,F$2) -> "services.rtd.subscriptionError" | G18: =RTD("tt.rtd",,$B18,G$2) -> "services.rtd.subscriptionError" | H18: =RTD("tt.rtd",,$B18,H$2) -> "services.rtd.subscriptionError" | I18: =RTD("tt.rtd",,$B18,I$2) -> "services.rtd.subscriptionError" | J18: =RTD("tt.rtd",,$B18,J$2) -> "services.rtd.subscriptionError" | K18: =IFERROR(IF(I18="Open",(E18+D18)/2,H18),H18) -> "services.rtd.subscriptionError" | L18: =IF(AND(I18="Open",G18>0),F18,K18) -> "services.rtd.subscriptionError"

Sheet CRA
A1: CRA | B1: MX
A2: CRA | B2: instrument ID | C2: Name | D2: Ask | E2: Bid | F2: Last | G2: CTQ | H2: Settle | I2: Status | J2: CTQ | K2: Mid | L2: Last
A3: =$A$2&LEFT('cont list_bg'!G6,1)&RIGHT('cont list_bg'!G6,1) -> CRAH6 | B3: =RTD("tt.rtd",,"Inst",$B$1,$A3) -> 5228476373492902639 | C3: =RIGHT(RTD("tt.rtd",,$B3,C$2),2) -> H6 | D3: =RTD("tt.rtd",,$B3,D$2) -> 97.71500 | E3: =RTD("tt.rtd",,$B3,E$2) -> 97.71250 | F3: =RTD("tt.rtd",,$B3,F$2) | G3: =RTD("tt.rtd",,$B3,G$2) -> 0 | H3: =RTD("tt.rtd",,$B3,H$2) -> 97.71250 | I3: =RTD("tt.rtd",,$B3,I$2) -> Open | J3: =RTD("tt.rtd",,$B3,J$2) -> 0 | K3: =IFERROR(IF(I3="Open",(E3+D3)/2,H3),H3) -> 97.71375 | L3: =IF(AND(I3="Open",G3>0),F3,K3) -> 97.71375
A4: =$A$2&LEFT('cont list_bg'!G7,1)&RIGHT('cont list_bg'!G7,1) -> CRAM6 | B4: =RTD("tt.rtd",,"Inst",$B$1,$A4) -> 11607487364946020404 | C4: =RIGHT(RTD("tt.rtd",,$B4,C$2),2) -> M6 | D4: =RTD("tt.rtd",,$B4,D$2) -> 97.6800 | E4: =RTD("tt.rtd",,$B4,E$2) -> 97.6750 | F4: =RTD("tt.rtd",,$B4,F$2) -> 97.6800 | G4: =RTD("tt.rtd",,$B4,G$2) -> 26 | H4: =RTD("tt.rtd",,$B4,H$2) -> 97.6700 | I4: =RTD("tt.rtd",,$B4,I$2) -> Open | J4: =RTD("tt.rtd",,$B4,J$2) -> 26 | K4: =IFERROR(IF(I4="Open",(E4+D4)/2,H4),H4) -> 97.6775 | L4: =IF(AND(I4="Open",G4>0),F4,K4) -> 97.6800
A5: =$A$2&LEFT('cont list_bg'!G8,1)&RIGHT('cont list_bg'!G8,1) -> CRAU6 | B5: =RTD("tt.rtd",,"Inst",$B$1,$A5) -> 2731941855341504934 | C5: =RIGHT(RTD("tt.rtd",,$B5,C$2),2) -> U6 | D5: =RTD("tt.rtd",,$B5,D$2) -> 97.4750 | E5: =RTD("tt.rtd",,$B5,E$2) -> 97.4700 | F5: =RTD("tt.rtd",,$B5,F$2) -> 97.4700 | G5: =RTD("tt.rtd",,$B5,G$2) -> 422 | H5: =RTD("tt.rtd",,$B5,H$2) -> 97.4500 | I5: =RTD("tt.rtd",,$B5,I$2) -> Open | J5: =RTD("tt.rtd",,$B5,J$2) -> 422 | K5: =IFERROR(IF(I5="Open",(E5+D5)/2,H5),H5) -> 97.4725 | L5: =IF(AND(I5="Open",G5>0),F5,K5) -> 97.4700
A6: =$A$2&LEFT('cont list_bg'!G9,1)&RIGHT('cont list_bg'!G9,1) -> CRAZ6 | B6: =RTD("tt.rtd",,"Inst",$B$1,$A6) -> 16116292756507691888 | C6: =RIGHT(RTD("tt.rtd",,$B6,C$2),2) -> Z6 | D6: =RTD("tt.rtd",,$B6,D$2) -> 97.2250 | E6: =RTD("tt.rtd",,$B6,E$2) -> 97.2200 | F6: =RTD("tt.rtd",,$B6,F$2) -> 97.2200 | G6: =RTD("tt.rtd",,$B6,G$2) -> 199 | H6: =RTD("tt.rtd",,$B6,H$2) -> 97.1850 | I6: =RTD("tt.rtd",,$B6,I$2) -> Open | J6: =RTD("tt.rtd",,$B6,J$2) -> 199 | K6: =IFERROR(IF(I6="Open",(E6+D6)/2,H6),H6) -> 97.2225 | L6: =IF(AND(I6="Open",G6>0),F6,K6) -> 97.2200
A7: =$A$2&LEFT('cont list_bg'!G10,1)&RIGHT('cont list_bg'!G10,1) -> CRAH7 | B7: =RTD("tt.rtd",,"Inst",$B$1,$A7) -> 1079631362856262921 | C7: =RIGHT(RTD("tt.rtd",,$B7,C$2),2) -> H7 | D7: =RTD("tt.rtd",,$B7,D$2) -> 97.0050 | E7: =RTD("tt.rtd",,$B7,E$2) -> 97.0000 | F7: =RTD("tt.rtd",,$B7,F$2) -> 97.0050 | G7: =RTD("tt.rtd",,$B7,G$2) -> 1018 | H7: =RTD("tt.rtd",,$B7,H$2) -> 96.9550 | I7: =RTD("tt.rtd",,$B7,I$2) -> Open | J7: =RTD("tt.rtd",,$B7,J$2) -> 1018 | K7: =IFERROR(IF(I7="Open",(E7+D7)/2,H7),H7) -> 97.0025 | L7: =IF(AND(I7="Open",G7>0),F7,K7) -> 97.0050
A8: =$A$2&LEFT('cont list_bg'!G11,1)&RIGHT('cont list_bg'!G11,1) -> CRAM7 | B8: =RTD("tt.rtd",,"Inst",$B$1,$A8) -> 8219882023429969 | C8: =RIGHT(RTD("tt.rtd",,$B8,C$2),2) -> M7 | D8: =RTD("tt.rtd",,$B8,D$2) -> 96.8850 | E8: =RTD("tt.rtd",,$B8,E$2) -> 96.8800 | F8: =RTD("tt.rtd",,$B8,F$2) -> 96.8850 | G8: =RTD("tt.rtd",,$B8,G$2) -> 9 | H8: =RTD("tt.rtd",,$B8,H$2) -> 96.8200 | I8: =RTD("tt.rtd",,$B8,I$2) -> Open | J8: =RTD("tt.rtd",,$B8,J$2) -> 9 | K8: =IFERROR(IF(I8="Open",(E8+D8)/2,H8),H8) -> 96.8825 | L8: =IF(AND(I8="Open",G8>0),F8,K8) -> 96.8850
A9: =$A$2&LEFT('cont list_bg'!G12,1)&RIGHT('cont list_bg'!G12,1) -> CRAU7 | B9: =RTD("tt.rtd",,"Inst",$B$1,$A9) -> 15050487581241061067 | C9: =RIGHT(RTD("tt.rtd",,$B9,C$2),2) -> U7 | D9: =RTD("tt.rtd",,$B9,D$2) -> 96.8350 | E9: =RTD("tt.rtd",,$B9,E$2) -> 96.8300 | F9: =RTD("tt.rtd",,$B9,F$2) -> 96.8350 | G9: =RTD("tt.rtd",,$B9,G$2) -> 1085 | H9: =RTD("tt.rtd",,$B9,H$2) -> 96.7700 | I9: =RTD("tt.rtd",,$B9,I$2) -> Open | J9: =RTD("tt.rtd",,$B9,J$2) -> 1085 | K9: =IFERROR(IF(I9="Open",(E9+D9)/2,H9),H9) -> 96.8325 | L9: =IF(AND(I9="Open",G9>0),F9,K9) -> 96.8350
A10: =$A$2&LEFT('cont list_bg'!G13,1)&RIGHT('cont list_bg'!G13,1) -> CRAZ7 | B10: =RTD("tt.rtd",,"Inst",$B$1,$A10) -> 14449049893797955023 | C10: =RIGHT(RTD("tt.rtd",,$B10,C$2),2) -> Z7 | D10: =RTD("tt.rtd",,$B10,D$2) -> 96.8150 | E10: =RTD("tt.rtd",,$B10,E$2) -> 96.8100 | F10: =RTD("tt.rtd",,$B10,F$2) -> 96.8150 | G10: =RTD("tt.rtd",,$B10,G$2) -> 93 | H10: =RTD("tt.rtd",,$B10,H$2) -> 96.7500 | I10: =RTD("tt.rtd",,$B10,I$2) -> Open | J10: =RTD("tt.rtd",,$B10,J$2) -> 93 | K10: =IFERROR(IF(I10="Open",(E10+D10)/2,H10),H10) -> 96.8125 | L10: =IF(AND(I10="Open",G10>0),F10,K10) -> 96.8150
A11: =$A$2&LEFT('cont list_bg'!G14,1)&RIGHT('cont list_bg'!G14,1) -> CRAH8 | B11: =RTD("tt.rtd",,"Inst",$B$1,$A11) -> 1605356167456418889 | C11: =RIGHT(RTD("tt.rtd",,$B11,C$2),2) -> H8 | D11: =RTD("tt.rtd",,$B11,D$2) -> 96.7850 | E11: =RTD("tt.rtd",,$B11,E$2) -> 96.7800 | F11: =RTD("tt.rtd",,$B11,F$2) -> 96.7850 | G11: =RTD("tt.rtd",,$B11,G$2) -> 77 | H11: =RTD("tt.rtd",,$B11,H$2) -> 96.7200 | I11: =RTD("tt.rtd",,$B11,I$2) -> Open | J11: =RTD("tt.rtd",,$B11,J$2) -> 77 | K11: =IFERROR(IF(I11="Open",(E11+D11)/2,H11),H11) -> 96.7825 | L11: =IF(AND(I11="Open",G11>0),F11,K11) -> 96.7850
A12: =$A$2&LEFT('cont list_bg'!G15,1)&RIGHT('cont list_bg'!G15,1) -> CRAM8 | B12: =RTD("tt.rtd",,"Inst",$B$1,$A12) -> 10341135123007474384 | C12: =RIGHT(RTD("tt.rtd",,$B12,C$2),2) -> M8 | D12: =RTD("tt.rtd",,$B12,D$2) -> 96.7700 | E12: =RTD("tt.rtd",,$B12,E$2) -> 96.7650 | F12: =RTD("tt.rtd",,$B12,F$2) -> 96.7700 | G12: =RTD("tt.rtd",,$B12,G$2) -> 90 | H12: =RTD("tt.rtd",,$B12,H$2) -> 96.7050 | I12: =RTD("tt.rtd",,$B12,I$2) -> Open | J12: =RTD("tt.rtd",,$B12,J$2) -> 90 | K12: =IFERROR(IF(I12="Open",(E12+D12)/2,H12),H12) -> 96.7675 | L12: =IF(AND(I12="Open",G12>0),F12,K12) -> 96.7700
A13: =$A$2&LEFT('cont list_bg'!G16,1)&RIGHT('cont list_bg'!G16,1) -> CRAU8 | B13: =RTD("tt.rtd",,"Inst",$B$1,$A13) -> 2953900796497171980 | C13: =RIGHT(RTD("tt.rtd",,$B13,C$2),2) -> U8 | D13: =RTD("tt.rtd",,$B13,D$2) -> 96.7650 | E13: =RTD("tt.rtd",,$B13,E$2) -> 96.7550 | F13: =RTD("tt.rtd",,$B13,F$2) -> 96.7600 | G13: =RTD("tt.rtd",,$B13,G$2) -> 1 | H13: =RTD("tt.rtd",,$B13,H$2) -> 96.7050 | I13: =RTD("tt.rtd",,$B13,I$2) -> Open | J13: =RTD("tt.rtd",,$B13,J$2) -> 1 | K13: =IFERROR(IF(I13="Open",(E13+D13)/2,H13),H13) -> 96.76 | L13: =IF(AND(I13="Open",G13>0),F13,K13) -> 96.7600
A14: =$A$2&LEFT('cont list_bg'!G17,1)&RIGHT('cont list_bg'!G17,1) -> CRAZ8 | B14: =RTD("tt.rtd",,"Inst",$B$1,$A14) -> 15227833694171614065 | C14: =RIGHT(RTD("tt.rtd",,$B14,C$2),2) -> Z8 | D14: =RTD("tt.rtd",,$B14,D$2) -> 96.7600 | E14: =RTD("tt.rtd",,$B14,E$2) -> 96.7500 | F14: =RTD("tt.rtd",,$B14,F$2) -> 96.7500 | G14: =RTD("tt.rtd",,$B14,G$2) -> 9 | H14: =RTD("tt.rtd",,$B14,H$2) -> 96.7050 | I14: =RTD("tt.rtd",,$B14,I$2) -> Open | J14: =RTD("tt.rtd",,$B14,J$2) -> 9 | K14: =IFERROR(IF(I14="Open",(E14+D14)/2,H14),H14) -> 96.755 | L14: =IF(AND(I14="Open",G14>0),F14,K14) -> 96.7500
A15: =$A$2&LEFT('cont list_bg'!G18,1)&RIGHT('cont list_bg'!G18,1) -> CRAH9 | B15: =RTD("tt.rtd",,"Inst",$B$1,$A15) -> "services.rtd.failedToFindInstrument" | C15: =RIGHT(RTD("tt.rtd",,$B15,C$2),2) -> t" | D15: =RTD("tt.rtd",,$B15,D$2) -> "services.rtd.invalidInstrumentFormat" | E15: =RTD("tt.rtd",,$B15,E$2) -> "services.rtd.invalidInstrumentFormat" | F15: =RTD("tt.rtd",,$B15,F$2) -> "services.rtd.invalidInstrumentFormat" | G15: =RTD("tt.rtd",,$B15,G$2) -> "services.rtd.invalidInstrumentFormat" | H15: =RTD("tt.rtd",,$B15,H$2) -> "services.rtd.invalidInstrumentFormat" | I15: =RTD("tt.rtd",,$B15,I$2) -> "services.rtd.invalidInstrumentFormat" | J15: =RTD("tt.rtd",,$B15,J$2) -> "services.rtd.invalidInstrumentFormat" | K15: =IFERROR(IF(I15="Open",(E15+D15)/2,H15),H15) -> "services.rtd.invalidInstrumentFormat" | L15: =IF(AND(I15="Open",G15>0),F15,K15) -> "services.rtd.invalidInstrumentFormat"

Sheet SR3 vs SO3
A1: SR3 vs SO3 | B1: CME
A2: SR3 vs SO3 | B2: instrument ID | C2: Name | D2: Ask | E2: Bid | F2: Last | G2: CTQ | H2: Settle | I2: Status | J2: CTQ | K2: Mid | L2: Last
A3: =RIGHT('SR3'!A3,2) -> H6 | C3: ='SR3'!C3 -> H6 | H3: ='SR3'!H3-'SO3'!H3 -> #VALUE! | K3: ='SR3'!K3-'SO3'!K3 -> #VALUE!
A4: =RIGHT('SR3'!A4,2) -> M6 | C4: ='SR3'!C4 -> M6 | H4: ='SR3'!H4-'SO3'!H4 -> #VALUE! | K4: ='SR3'!K4-'SO3'!K4 -> #VALUE!
A5: =RIGHT('SR3'!A5,2) -> U6 | C5: ='SR3'!C5 -> U6 | H5: ='SR3'!H5-'SO3'!H5 -> #VALUE! | K5: ='SR3'!K5-'SO3'!K5 -> #VALUE!
A6: =RIGHT('SR3'!A6,2) -> Z6 | C6: ='SR3'!C6 -> Z6 | H6: ='SR3'!H6-'SO3'!H6 -> #VALUE! | K6: ='SR3'!K6-'SO3'!K6 -> #VALUE!
A7: =RIGHT('SR3'!A7,2) -> H7 | C7: ='SR3'!C7 -> H7 | H7: ='SR3'!H7-'SO3'!H7 -> #VALUE! | K7: ='SR3'!K7-'SO3'!K7 -> #VALUE!
A8: =RIGHT('SR3'!A8,2) -> M7 | C8: ='SR3'!C8 -> M7 | H8: ='SR3'!H8-'SO3'!H8 -> #VALUE! | K8: ='SR3'!K8-'SO3'!K8 -> #VALUE!
A9: =RIGHT('SR3'!A9,2) -> U7 | C9: ='SR3'!C9 -> U7 | H9: ='SR3'!H9-'SO3'!H9 -> #VALUE! | K9: ='SR3'!K9-'SO3'!K9 -> #VALUE!
A10: =RIGHT('SR3'!A10,2) -> Z7 | C10: ='SR3'!C10 -> Z7 | H10: ='SR3'!H10-'SO3'!H10 -> #VALUE! | K10: ='SR3'!K10-'SO3'!K10 -> #VALUE!
A11: =RIGHT('SR3'!A11,2) -> H8 | C11: ='SR3'!C11 -> H8 | H11: ='SR3'!H11-'SO3'!H11 -> #VALUE! | K11: ='SR3'!K11-'SO3'!K11 -> #VALUE!
A12: =RIGHT('SR3'!A12,2) -> M8 | C12: ='SR3'!C12 -> M8 | H12: ='SR3'!H12-'SO3'!H12 -> #VALUE! | K12: ='SR3'!K12-'SO3'!K12 -> #VALUE!
A13: =RIGHT('SR3'!A13,2) -> U8 | C13: ='SR3'!C13 -> U8 | H13: ='SR3'!H13-'SO3'!H13 -> #VALUE! | K13: ='SR3'!K13-'SO3'!K13 -> #VALUE!
A14: =RIGHT('SR3'!A14,2) -> Z8 | C14: ='SR3'!C14 -> Z8 | H14: ='SR3'!H14-'SO3'!H14 -> #VALUE! | K14: ='SR3'!K14-'SO3'!K14 -> #VALUE!
... A26: =RIGHT('SR3'!A26,2) -> Z1 | C26: ='SR3'!C26 -> Z1 | H26: ='SR3'!H26-'SO3'!H26 -> #VALUE! | K26: ='SR3'!K26-'SO3'!K26 -> #VALUE!

Sheet SR3 vs ER
A1: SR3 vs SO3 | B1: CME
A2: SR3 vs SO3 | B2: instrument ID | C2: Name | D2: Ask | E2: Bid | F2: Last | G2: CTQ | H2: Settle | I2: Status | J2: CTQ | K2: Mid | L2: Last
A4: =RIGHT('SR3'!A4,2) -> M6 | C4: ='SR3'!C4 -> M6 | H4: ='SR3'!H4-ER!H4 -> #VALUE! | K4: ='SR3'!K4-'SO3'!K4 -> #VALUE!
A5: =RIGHT('SR3'!A5,2) -> U6 | C5: ='SR3'!C5 -> U6 | H5: ='SR3'!H5-ER!H5 -> #VALUE! | K5: ='SR3'!K5-'SO3'!K5 -> #VALUE!
A6: =RIGHT('SR3'!A6,2) -> Z6 | C6: ='SR3'!C6 -> Z6 | H6: ='SR3'!H6-ER!H6 -> #VALUE! | K6: ='SR3'!K6-'SO3'!K6 -> #VALUE!
A7: =RIGHT('SR3'!A7,2) -> H7 | C7: ='SR3'!C7 -> H7 | H7: ='SR3'!H7-ER!H7 -> #VALUE! | K7: ='SR3'!K7-'SO3'!K7 -> #VALUE!
A8: =RIGHT('SR3'!A8,2) -> M7 | C8: ='SR3'!C8 -> M7 | H8: ='SR3'!H8-ER!H8 -> #VALUE! | K8: ='SR3'!K8-'SO3'!K8 -> #VALUE!
A9: =RIGHT('SR3'!A9,2) -> U7 | C9: ='SR3'!C9 -> U7 | H9: ='SR3'!H9-ER!H9 -> #VALUE! | K9: ='SR3'!K9-'SO3'!K9 -> #VALUE!
A10: =RIGHT('SR3'!A10,2) -> Z7 | C10: ='SR3'!C10 -> Z7 | H10: ='SR3'!H10-ER!H10 -> #VALUE! | K10: ='SR3'!K10-'SO3'!K10 -> #VALUE!
A11: =RIGHT('SR3'!A11,2) -> H8 | C11: ='SR3'!C11 -> H8 | H11: ='SR3'!H11-ER!H11 -> #VALUE! | K11: ='SR3'!K11-'SO3'!K11 -> #VALUE!
A12: =RIGHT('SR3'!A12,2) -> M8 | C12: ='SR3'!C12 -> M8 | H12: ='SR3'!H12-ER!H12 -> #VALUE! | K12: ='SR3'!K12-'SO3'!K12 -> #VALUE!
A13: =RIGHT('SR3'!A13,2) -> U8 | C13: ='SR3'!C13 -> U8 | H13: ='SR3'!H13-ER!H13 -> #VALUE! | K13: ='SR3'!K13-'SO3'!K13 -> #VALUE!
A14: =RIGHT('SR3'!A14,2) -> Z8 | C14: ='SR3'!C14 -> Z8 | H14: ='SR3'!H14-ER!H14 -> #VALUE! | K14: ='SR3'!K14-'SO3'!K14 -> #VALUE!
A15: =RIGHT('SR3'!A15,2) -> H9 | C15: ='SR3'!C15 -> H9 | H15: ='SR3'!H15-ER!H15 -> #VALUE! | K15: ='SR3'!K15-'SO3'!K15 -> #VALUE!
... A26: =RIGHT('SR3'!A26,2) -> Z1 | C26: ='SR3'!C26 -> Z1 | H26: ='SR3'!H26-ER!H26 -> #VALUE! | K26: ='SR3'!K26-'SO3'!K26 -> #VALUE!

Sheet ER vs SO3
A1: SR3 vs SO3 | B1: CME
A2: SR3 vs SO3 | B2: instrument ID | C2: Name | D2: Ask | E2: Bid | F2: Last | G2: CTQ | H2: Settle | I2: Status | J2: CTQ | K2: Mid | L2: Last
A4: =RIGHT('SR3'!A4,2) -> M6 | C4: ='SR3'!C4 -> M6 | H4: =ER!H4-'SO3'!H4 -> #VALUE! | K4: =ER!K4-'SO3'!K4 -> #VALUE!
A5: =RIGHT('SR3'!A5,2) -> U6 | C5: ='SR3'!C5 -> U6 | H5: =ER!H5-'SO3'!H5 -> #VALUE! | K5: =ER!K5-'SO3'!K5 -> #VALUE!
A6: =RIGHT('SR3'!A6,2) -> Z6 | C6: ='SR3'!C6 -> Z6 | H6: =ER!H6-'SO3'!H6 -> #VALUE! | K6: =ER!K6-'SO3'!K6 -> #VALUE!
A7: =RIGHT('SR3'!A7,2) -> H7 | C7: ='SR3'!C7 -> H7 | H7: =ER!H7-'SO3'!H7 -> #VALUE! | K7: =ER!K7-'SO3'!K7 -> #VALUE!
A8: =RIGHT('SR3'!A8,2) -> M7 | C8: ='SR3'!C8 -> M7 | H8: =ER!H8-'SO3'!H8 -> #VALUE! | K8: =ER!K8-'SO3'!K8 -> #VALUE!
A9: =RIGHT('SR3'!A9,2) -> U7 | C9: ='SR3'!C9 -> U7 | H9: =ER!H9-'SO3'!H9 -> #VALUE! | K9: =ER!K9-'SO3'!K9 -> #VALUE!
A10: =RIGHT('SR3'!A10,2) -> Z7 | C10: ='SR3'!C10 -> Z7 | H10: =ER!H10-'SO3'!H10 -> #VALUE! | K10: =ER!K10-'SO3'!K10 -> #VALUE!
A11: =RIGHT('SR3'!A11,2) -> H8 | C11: ='SR3'!C11 -> H8 | H11: =ER!H11-'SO3'!H11 -> #VALUE! | K11: =ER!K11-'SO3'!K11 -> #VALUE!
A12: =RIGHT('SR3'!A12,2) -> M8 | C12: ='SR3'!C12 -> M8 | H12: =ER!H12-'SO3'!H12 -> #VALUE! | K12: =ER!K12-'SO3'!K12 -> #VALUE!
A13: =RIGHT('SR3'!A13,2) -> U8 | C13: ='SR3'!C13 -> U8 | H13: =ER!H13-'SO3'!H13 -> #VALUE! | K13: =ER!K13-'SO3'!K13 -> #VALUE!
A14: =RIGHT('SR3'!A14,2) -> Z8 | C14: ='SR3'!C14 -> Z8 | H14: =ER!H14-'SO3'!H14 -> #VALUE! | K14: =ER!K14-'SO3'!K14 -> #VALUE!
A15: =RIGHT('SR3'!A15,2) -> H9 | C15: ='SR3'!C15 -> H9 | H15: =ER!H15-'SO3'!H15 -> #VALUE! | K15: =ER!K15-'SO3'!K15 -> #VALUE!
... A26: =RIGHT('SR3'!A26,2) -> Z1 | C26: ='SR3'!C26 -> Z1 | H26: =ER!H26-'SO3'!H26 -> #VALUE! | K26: =ER!K26-'SO3'!K26 -> #VALUE!

Sheet ER3
A1: ESTR | B1: ICE_L
A2: ER3 | B2: instrument ID | C2: Name | D2: Ask | E2: Bid | F2: Last | G2: CTQ | H2: Settle | I2: Status | J2: CTQ | K2: Mid | L2: Last
A3: =$A$2&" FM"&LEFT('cont list_bg'!G6,1)&"00"&RIGHT('cont list_bg'!G6,2)&"!" -> ER3 FMH0026! | B3: =RTD("tt.rtd",,"Inst",$B$1,$A3) -> 16193655064494849323 | C3: =MID(RTD("tt.rtd",,$B3,C$2),7,1)&MID(RTD("tt.rtd",,$B3,C$2),11,1) -> H6 | D3: =RTD("tt.rtd",,$B3,D$2) -> 98.0650 | E3: =RTD("tt.rtd",,$B3,E$2) -> 98.0625 | F3: =RTD("tt.rtd",,$B3,F$2) -> 98.0650 | G3: =RTD("tt.rtd",,$B3,G$2) -> 12 | H3: =RTD("tt.rtd",,$B3,H$2) -> 98.0625 | I3: =RTD("tt.rtd",,$B3,I$2) -> Open | J3: =RTD("tt.rtd",,$B3,J$2) -> 12 | K3: =IFERROR(IF(I3="Open",(E3+D3)/2,H3),H3) -> 98.06375 | L3: =IF(AND(I3="Open",G3>0),F3,K3) -> 98.0650
A4: =$A$2&" FM"&LEFT('cont list_bg'!G7,1)&"00"&RIGHT('cont list_bg'!G7,2)&"!" -> ER3 FMM0026! | B4: =RTD("tt.rtd",,"Inst",$B$1,$A4) -> 17887834827094596965 | C4: =MID(RTD("tt.rtd",,$B4,C$2),7,1)&MID(RTD("tt.rtd",,$B4,C$2),11,1) -> M6 | D4: =RTD("tt.rtd",,$B4,D$2) -> "services.rtd.subscriptionError" | E4: =RTD("tt.rtd",,$B4,E$2) -> "services.rtd.subscriptionError" | F4: =RTD("tt.rtd",,$B4,F$2) -> "services.rtd.subscriptionError" | G4: =RTD("tt.rtd",,$B4,G$2) -> "services.rtd.subscriptionError" | H4: =RTD("tt.rtd",,$B4,H$2) -> "services.rtd.subscriptionError" | I4: =RTD("tt.rtd",,$B4,I$2) -> "services.rtd.subscriptionError" | J4: =RTD("tt.rtd",,$B4,J$2) -> "services.rtd.subscriptionError" | K4: =IFERROR(IF(I4="Open",(E4+D4)/2,H4),H4) -> "services.rtd.subscriptionError" | L4: =IF(AND(I4="Open",G4>0),F4,K4) -> "services.rtd.subscriptionError"
A5: =$A$2&" FM"&LEFT('cont list_bg'!G8,1)&"00"&RIGHT('cont list_bg'!G8,2)&"!" -> ER3 FMU0026! | B5: =RTD("tt.rtd",,"Inst",$B$1,$A5) -> 13942165873650377178 | C5: =MID(RTD("tt.rtd",,$B5,C$2),7,1)&MID(RTD("tt.rtd",,$B5,C$2),11,1) -> U6 | D5: =RTD("tt.rtd",,$B5,D$2) -> "services.rtd.subscriptionError" | E5: =RTD("tt.rtd",,$B5,E$2) -> "services.rtd.subscriptionError" | F5: =RTD("tt.rtd",,$B5,F$2) -> "services.rtd.subscriptionError" | G5: =RTD("tt.rtd",,$B5,G$2) -> "services.rtd.subscriptionError" | H5: =RTD("tt.rtd",,$B5,H$2) -> "services.rtd.subscriptionError" | I5: =RTD("tt.rtd",,$B5,I$2) -> "services.rtd.subscriptionError" | J5: =RTD("tt.rtd",,$B5,J$2) -> "services.rtd.subscriptionError" | K5: =IFERROR(IF(I5="Open",(E5+D5)/2,H5),H5) -> "services.rtd.subscriptionError" | L5: =IF(AND(I5="Open",G5>0),F5,K5) -> "services.rtd.subscriptionError"
A6: =$A$2&" FM"&LEFT('cont list_bg'!G9,1)&"00"&RIGHT('cont list_bg'!G9,2)&"!" -> ER3 FMZ0026! | B6: =RTD("tt.rtd",,"Inst",$B$1,$A6) -> 4095991086729837254 | C6: =MID(RTD("tt.rtd",,$B6,C$2),7,1)&MID(RTD("tt.rtd",,$B6,C$2),11,1) -> Z6 | D6: =RTD("tt.rtd",,$B6,D$2) -> "services.rtd.subscriptionError" | E6: =RTD("tt.rtd",,$B6,E$2) -> "services.rtd.subscriptionError" | F6: =RTD("tt.rtd",,$B6,F$2) -> "services.rtd.subscriptionError" | G6: =RTD("tt.rtd",,$B6,G$2) -> "services.rtd.subscriptionError" | H6: =RTD("tt.rtd",,$B6,H$2) -> "services.rtd.subscriptionError" | I6: =RTD("tt.rtd",,$B6,I$2) -> "services.rtd.subscriptionError" | J6: =RTD("tt.rtd",,$B6,J$2) -> "services.rtd.subscriptionError" | K6: =IFERROR(IF(I6="Open",(E6+D6)/2,H6),H6) -> "services.rtd.subscriptionError" | L6: =IF(AND(I6="Open",G6>0),F6,K6) -> "services.rtd.subscriptionError"
